<robot name="planar_arm">
  <link name="base_link" />
  <link name="link1" />
  <link name="link2" />
  <link name="link3" />
  <link name="link4" />
  <link name="link5" />
  <link name="link6" />
  <link name="tool" />

  <joint name="joint1" type="revolute">
    <parent link="base_link" />
    <child link="link1" />
    <origin xyz="0 0 0.1" rpy="0 0 0" />
    <axis xyz="0 0 1" />
    <limit lower="-3.1416" upper="3.1416" effort="1" velocity="1" />
  </joint>

  <joint name="joint2" type="revolute">
    <parent link="link1" />
    <child link="link2" />
    <origin xyz="0.2 0 0" rpy="0 0 0" />
    <axis xyz="0 1 0" />
    <limit lower="-3.1416" upper="3.1416" effort="1" velocity="1" />
  </joint>

  <joint name="joint3" type="revolute">
    <parent link="link2" />
    <child link="link3" />
    <origin xyz="0.2 0 0" rpy="0 0 0" />
    <axis xyz="1 0 0" />
    <limit lower="-3.1416" upper="3.1416" effort="1" velocity="1" />
  </joint>

  <joint name="joint4" type="revolute">
    <parent link="link3" />
    <child link="link4" />
    <origin xyz="0.2 0 0" rpy="0 0 0" />
    <axis xyz="0 0 1" />
    <limit lower="-3.1416" upper="3.1416" effort="1" velocity="1" />
  </joint>

  <joint name="joint5" type="revolute">
    <parent link="link4" />
    <child link="link5" />
    <origin xyz="0.15 0 0" rpy="0 0 0" />
    <axis xyz="0 1 0" />
    <limit lower="-3.1416" upper="3.1416" effort="1" velocity="1" />
  </joint>

  <joint name="joint6" type="revolute">
    <parent link="link5" />
    <child link="link6" />
    <origin xyz="0.1 0 0" rpy="0 0 0" />
    <axis xyz="1 0 0" />
    <limit lower="-3.1416" upper="3.1416" effort="1" velocity="1" />
  </joint>

  <joint name="tool_joint" type="fixed">
    <parent link="link6" />
    <child link="tool" />
    <origin xyz="0.1 0 0" rpy="0 0 0" />
  </joint>
</robot>